2025-08-18 14:39:27,208 [ERROR] [root:2049] [_finalize_session] Erro ao enviar mensagem WhatsApp: 429 Client Error: Too Many Requests for url: https://messages-sandbox.nexmo.com/v1/messages
Traceback (most recent call last):
  File "/app/app.py", line 2045, in _finalize_session
    vonage_client.enviar_whatsapp(response_text)
  File "/app/communication/cliente_vonage.py", line 43, in enviar_whatsapp
    resposta.raise_for_status()
  File "/usr/local/lib/python3.9/site-packages/requests/models.py", line 1026, in raise_for_status
    raise HTTPError(http_error_msg, response=self)
requests.exceptions.HTTPError: 429 Client Error: Too Many Requests for url: https://messages-sandbox.nexmo.com/v1/messages
2025-08-18 14:39:42,963 [ERROR] [root:2049] [_finalize_session] Erro ao enviar mensagem WhatsApp: 429 Client Error: Too Many Requests for url: https://messages-sandbox.nexmo.com/v1/messages
Traceback (most recent call last):
  File "/app/app.py", line 2045, in _finalize_session
    vonage_client.enviar_whatsapp(response_text)
  File "/app/communication/cliente_vonage.py", line 43, in enviar_whatsapp
    resposta.raise_for_status()
  File "/usr/local/lib/python3.9/site-packages/requests/models.py", line 1026, in raise_for_status
    raise HTTPError(http_error_msg, response=self)
requests.exceptions.HTTPError: 429 Client Error: Too Many Requests for url: https://messages-sandbox.nexmo.com/v1/messages
2025-08-18 14:40:01,489 [ERROR] [root:2049] [_finalize_session] Erro ao enviar mensagem WhatsApp: 429 Client Error: Too Many Requests for url: https://messages-sandbox.nexmo.com/v1/messages
Traceback (most recent call last):
  File "/app/app.py", line 2045, in _finalize_session
    vonage_client.enviar_whatsapp(response_text)
  File "/app/communication/cliente_vonage.py", line 43, in enviar_whatsapp
    resposta.raise_for_status()
  File "/usr/local/lib/python3.9/site-packages/requests/models.py", line 1026, in raise_for_status
    raise HTTPError(http_error_msg, response=self)
requests.exceptions.HTTPError: 429 Client Error: Too Many Requests for url: https://messages-sandbox.nexmo.com/v1/messages
2025-08-18 14:40:26,378 [ERROR] [root:2049] [_finalize_session] Erro ao enviar mensagem WhatsApp: 429 Client Error: Too Many Requests for url: https://messages-sandbox.nexmo.com/v1/messages
Traceback (most recent call last):
  File "/app/app.py", line 2045, in _finalize_session
    vonage_client.enviar_whatsapp(response_text)
  File "/app/communication/cliente_vonage.py", line 43, in enviar_whatsapp
    resposta.raise_for_status()
  File "/usr/local/lib/python3.9/site-packages/requests/models.py", line 1026, in raise_for_status
    raise HTTPError(http_error_msg, response=self)
requests.exceptions.HTTPError: 429 Client Error: Too Many Requests for url: https://messages-sandbox.nexmo.com/v1/messages
2025-08-18 14:40:41,417 [ERROR] [root:2049] [_finalize_session] Erro ao enviar mensagem WhatsApp: 429 Client Error: Too Many Requests for url: https://messages-sandbox.nexmo.com/v1/messages
Traceback (most recent call last):
  File "/app/app.py", line 2045, in _finalize_session
    vonage_client.enviar_whatsapp(response_text)
  File "/app/communication/cliente_vonage.py", line 43, in enviar_whatsapp
    resposta.raise_for_status()
  File "/usr/local/lib/python3.9/site-packages/requests/models.py", line 1026, in raise_for_status
    raise HTTPError(http_error_msg, response=self)
requests.exceptions.HTTPError: 429 Client Error: Too Many Requests for url: https://messages-sandbox.nexmo.com/v1/messages
2025-08-18 14:40:59,486 [ERROR] [root:2049] [_finalize_session] Erro ao enviar mensagem WhatsApp: 429 Client Error: Too Many Requests for url: https://messages-sandbox.nexmo.com/v1/messages
Traceback (most recent call last):
  File "/app/app.py", line 2045, in _finalize_session
    vonage_client.enviar_whatsapp(response_text)
  File "/app/communication/cliente_vonage.py", line 43, in enviar_whatsapp
    resposta.raise_for_status()
  File "/usr/local/lib/python3.9/site-packages/requests/models.py", line 1026, in raise_for_status
    raise HTTPError(http_error_msg, response=self)
requests.exceptions.HTTPError: 429 Client Error: Too Many Requests for url: https://messages-sandbox.nexmo.com/v1/messages
2025-08-18 14:41:18,344 [ERROR] [root:2049] [_finalize_session] Erro ao enviar mensagem WhatsApp: 429 Client Error: Too Many Requests for url: https://messages-sandbox.nexmo.com/v1/messages
Traceback (most recent call last):
  File "/app/app.py", line 2045, in _finalize_session
    vonage_client.enviar_whatsapp(response_text)
  File "/app/communication/cliente_vonage.py", line 43, in enviar_whatsapp
    resposta.raise_for_status()
  File "/usr/local/lib/python3.9/site-packages/requests/models.py", line 1026, in raise_for_status
    raise HTTPError(http_error_msg, response=self)
requests.exceptions.HTTPError: 429 Client Error: Too Many Requests for url: https://messages-sandbox.nexmo.com/v1/messages
2025-08-18 14:41:46,048 [ERROR] [root:2049] [_finalize_session] Erro ao enviar mensagem WhatsApp: 429 Client Error: Too Many Requests for url: https://messages-sandbox.nexmo.com/v1/messages
Traceback (most recent call last):
  File "/app/app.py", line 2045, in _finalize_session
    vonage_client.enviar_whatsapp(response_text)
  File "/app/communication/cliente_vonage.py", line 43, in enviar_whatsapp
    resposta.raise_for_status()
  File "/usr/local/lib/python3.9/site-packages/requests/models.py", line 1026, in raise_for_status
    raise HTTPError(http_error_msg, response=self)
requests.exceptions.HTTPError: 429 Client Error: Too Many Requests for url: https://messages-sandbox.nexmo.com/v1/messages
2025-08-18 14:43:31,768 [ERROR] [root:2049] [_finalize_session] Erro ao enviar mensagem WhatsApp: 429 Client Error: Too Many Requests for url: https://messages-sandbox.nexmo.com/v1/messages
Traceback (most recent call last):
  File "/app/app.py", line 2045, in _finalize_session
    vonage_client.enviar_whatsapp(response_text)
  File "/app/communication/cliente_vonage.py", line 43, in enviar_whatsapp
    resposta.raise_for_status()
  File "/usr/local/lib/python3.9/site-packages/requests/models.py", line 1026, in raise_for_status
    raise HTTPError(http_error_msg, response=self)
requests.exceptions.HTTPError: 429 Client Error: Too Many Requests for url: https://messages-sandbox.nexmo.com/v1/messages
2025-08-18 14:43:53,659 [ERROR] [root:2049] [_finalize_session] Erro ao enviar mensagem WhatsApp: 429 Client Error: Too Many Requests for url: https://messages-sandbox.nexmo.com/v1/messages
Traceback (most recent call last):
  File "/app/app.py", line 2045, in _finalize_session
    vonage_client.enviar_whatsapp(response_text)
  File "/app/communication/cliente_vonage.py", line 43, in enviar_whatsapp
    resposta.raise_for_status()
  File "/usr/local/lib/python3.9/site-packages/requests/models.py", line 1026, in raise_for_status
    raise HTTPError(http_error_msg, response=self)
requests.exceptions.HTTPError: 429 Client Error: Too Many Requests for url: https://messages-sandbox.nexmo.com/v1/messages
2025-08-18 14:44:22,752 [ERROR] [root:2049] [_finalize_session] Erro ao enviar mensagem WhatsApp: 429 Client Error: Too Many Requests for url: https://messages-sandbox.nexmo.com/v1/messages
Traceback (most recent call last):
  File "/app/app.py", line 2045, in _finalize_session
    vonage_client.enviar_whatsapp(response_text)
  File "/app/communication/cliente_vonage.py", line 43, in enviar_whatsapp
    resposta.raise_for_status()
  File "/usr/local/lib/python3.9/site-packages/requests/models.py", line 1026, in raise_for_status
    raise HTTPError(http_error_msg, response=self)
requests.exceptions.HTTPError: 429 Client Error: Too Many Requests for url: https://messages-sandbox.nexmo.com/v1/messages
2025-08-18 14:44:38,331 [ERROR] [root:2049] [_finalize_session] Erro ao enviar mensagem WhatsApp: 429 Client Error: Too Many Requests for url: https://messages-sandbox.nexmo.com/v1/messages
Traceback (most recent call last):
  File "/app/app.py", line 2045, in _finalize_session
    vonage_client.enviar_whatsapp(response_text)
  File "/app/communication/cliente_vonage.py", line 43, in enviar_whatsapp
    resposta.raise_for_status()
  File "/usr/local/lib/python3.9/site-packages/requests/models.py", line 1026, in raise_for_status
    raise HTTPError(http_error_msg, response=self)
requests.exceptions.HTTPError: 429 Client Error: Too Many Requests for url: https://messages-sandbox.nexmo.com/v1/messages
2025-08-18 14:44:44,117 [ERROR] [root:2049] [_finalize_session] Erro ao enviar mensagem WhatsApp: 429 Client Error: Too Many Requests for url: https://messages-sandbox.nexmo.com/v1/messages
Traceback (most recent call last):
  File "/app/app.py", line 2045, in _finalize_session
    vonage_client.enviar_whatsapp(response_text)
  File "/app/communication/cliente_vonage.py", line 43, in enviar_whatsapp
    resposta.raise_for_status()
  File "/usr/local/lib/python3.9/site-packages/requests/models.py", line 1026, in raise_for_status
    raise HTTPError(http_error_msg, response=self)
requests.exceptions.HTTPError: 429 Client Error: Too Many Requests for url: https://messages-sandbox.nexmo.com/v1/messages
2025-08-18 14:44:58,053 [ERROR] [root:2049] [_finalize_session] Erro ao enviar mensagem WhatsApp: 429 Client Error: Too Many Requests for url: https://messages-sandbox.nexmo.com/v1/messages
Traceback (most recent call last):
  File "/app/app.py", line 2045, in _finalize_session
    vonage_client.enviar_whatsapp(response_text)
  File "/app/communication/cliente_vonage.py", line 43, in enviar_whatsapp
    resposta.raise_for_status()
  File "/usr/local/lib/python3.9/site-packages/requests/models.py", line 1026, in raise_for_status
    raise HTTPError(http_error_msg, response=self)
requests.exceptions.HTTPError: 429 Client Error: Too Many Requests for url: https://messages-sandbox.nexmo.com/v1/messages
2025-08-18 14:45:17,476 [ERROR] [root:2049] [_finalize_session] Erro ao enviar mensagem WhatsApp: 429 Client Error: Too Many Requests for url: https://messages-sandbox.nexmo.com/v1/messages
Traceback (most recent call last):
  File "/app/app.py", line 2045, in _finalize_session
    vonage_client.enviar_whatsapp(response_text)
  File "/app/communication/cliente_vonage.py", line 43, in enviar_whatsapp
    resposta.raise_for_status()
  File "/usr/local/lib/python3.9/site-packages/requests/models.py", line 1026, in raise_for_status
    raise HTTPError(http_error_msg, response=self)
requests.exceptions.HTTPError: 429 Client Error: Too Many Requests for url: https://messages-sandbox.nexmo.com/v1/messages
2025-08-18 14:45:29,425 [ERROR] [root:2049] [_finalize_session] Erro ao enviar mensagem WhatsApp: 429 Client Error: Too Many Requests for url: https://messages-sandbox.nexmo.com/v1/messages
Traceback (most recent call last):
  File "/app/app.py", line 2045, in _finalize_session
    vonage_client.enviar_whatsapp(response_text)
  File "/app/communication/cliente_vonage.py", line 43, in enviar_whatsapp
    resposta.raise_for_status()
  File "/usr/local/lib/python3.9/site-packages/requests/models.py", line 1026, in raise_for_status
    raise HTTPError(http_error_msg, response=self)
requests.exceptions.HTTPError: 429 Client Error: Too Many Requests for url: https://messages-sandbox.nexmo.com/v1/messages
2025-08-18 14:45:42,943 [ERROR] [root:2049] [_finalize_session] Erro ao enviar mensagem WhatsApp: 429 Client Error: Too Many Requests for url: https://messages-sandbox.nexmo.com/v1/messages
Traceback (most recent call last):
  File "/app/app.py", line 2045, in _finalize_session
    vonage_client.enviar_whatsapp(response_text)
  File "/app/communication/cliente_vonage.py", line 43, in enviar_whatsapp
    resposta.raise_for_status()
  File "/usr/local/lib/python3.9/site-packages/requests/models.py", line 1026, in raise_for_status
    raise HTTPError(http_error_msg, response=self)
requests.exceptions.HTTPError: 429 Client Error: Too Many Requests for url: https://messages-sandbox.nexmo.com/v1/messages
2025-08-18 14:46:04,915 [ERROR] [root:2049] [_finalize_session] Erro ao enviar mensagem WhatsApp: 429 Client Error: Too Many Requests for url: https://messages-sandbox.nexmo.com/v1/messages
Traceback (most recent call last):
  File "/app/app.py", line 2045, in _finalize_session
    vonage_client.enviar_whatsapp(response_text)
  File "/app/communication/cliente_vonage.py", line 43, in enviar_whatsapp
    resposta.raise_for_status()
  File "/usr/local/lib/python3.9/site-packages/requests/models.py", line 1026, in raise_for_status
    raise HTTPError(http_error_msg, response=self)
requests.exceptions.HTTPError: 429 Client Error: Too Many Requests for url: https://messages-sandbox.nexmo.com/v1/messages
2025-08-18 14:46:21,744 [ERROR] [root:2049] [_finalize_session] Erro ao enviar mensagem WhatsApp: 429 Client Error: Too Many Requests for url: https://messages-sandbox.nexmo.com/v1/messages
Traceback (most recent call last):
  File "/app/app.py", line 2045, in _finalize_session
    vonage_client.enviar_whatsapp(response_text)
  File "/app/communication/cliente_vonage.py", line 43, in enviar_whatsapp
    resposta.raise_for_status()
  File "/usr/local/lib/python3.9/site-packages/requests/models.py", line 1026, in raise_for_status
    raise HTTPError(http_error_msg, response=self)
requests.exceptions.HTTPError: 429 Client Error: Too Many Requests for url: https://messages-sandbox.nexmo.com/v1/messages
2025-08-18 14:48:28,771 [ERROR] [root:2049] [_finalize_session] Erro ao enviar mensagem WhatsApp: 429 Client Error: Too Many Requests for url: https://messages-sandbox.nexmo.com/v1/messages
Traceback (most recent call last):
  File "/app/app.py", line 2045, in _finalize_session
    vonage_client.enviar_whatsapp(response_text)
  File "/app/communication/cliente_vonage.py", line 43, in enviar_whatsapp
    resposta.raise_for_status()
  File "/usr/local/lib/python3.9/site-packages/requests/models.py", line 1026, in raise_for_status
    raise HTTPError(http_error_msg, response=self)
requests.exceptions.HTTPError: 429 Client Error: Too Many Requests for url: https://messages-sandbox.nexmo.com/v1/messages
2025-08-18 14:48:42,612 [ERROR] [root:2049] [_finalize_session] Erro ao enviar mensagem WhatsApp: 429 Client Error: Too Many Requests for url: https://messages-sandbox.nexmo.com/v1/messages
Traceback (most recent call last):
  File "/app/app.py", line 2045, in _finalize_session
    vonage_client.enviar_whatsapp(response_text)
  File "/app/communication/cliente_vonage.py", line 43, in enviar_whatsapp
    resposta.raise_for_status()
  File "/usr/local/lib/python3.9/site-packages/requests/models.py", line 1026, in raise_for_status
    raise HTTPError(http_error_msg, response=self)
requests.exceptions.HTTPError: 429 Client Error: Too Many Requests for url: https://messages-sandbox.nexmo.com/v1/messages
2025-08-18 14:48:50,974 [ERROR] [root:2049] [_finalize_session] Erro ao enviar mensagem WhatsApp: 429 Client Error: Too Many Requests for url: https://messages-sandbox.nexmo.com/v1/messages
Traceback (most recent call last):
  File "/app/app.py", line 2045, in _finalize_session
    vonage_client.enviar_whatsapp(response_text)
  File "/app/communication/cliente_vonage.py", line 43, in enviar_whatsapp
    resposta.raise_for_status()
  File "/usr/local/lib/python3.9/site-packages/requests/models.py", line 1026, in raise_for_status
    raise HTTPError(http_error_msg, response=self)
requests.exceptions.HTTPError: 429 Client Error: Too Many Requests for url: https://messages-sandbox.nexmo.com/v1/messages
2025-08-18 14:49:07,764 [ERROR] [root:2049] [_finalize_session] Erro ao enviar mensagem WhatsApp: 429 Client Error: Too Many Requests for url: https://messages-sandbox.nexmo.com/v1/messages
Traceback (most recent call last):
  File "/app/app.py", line 2045, in _finalize_session
    vonage_client.enviar_whatsapp(response_text)
  File "/app/communication/cliente_vonage.py", line 43, in enviar_whatsapp
    resposta.raise_for_status()
  File "/usr/local/lib/python3.9/site-packages/requests/models.py", line 1026, in raise_for_status
    raise HTTPError(http_error_msg, response=self)
requests.exceptions.HTTPError: 429 Client Error: Too Many Requests for url: https://messages-sandbox.nexmo.com/v1/messages
2025-08-18 14:49:13,226 [ERROR] [root:2049] [_finalize_session] Erro ao enviar mensagem WhatsApp: 429 Client Error: Too Many Requests for url: https://messages-sandbox.nexmo.com/v1/messages
Traceback (most recent call last):
  File "/app/app.py", line 2045, in _finalize_session
    vonage_client.enviar_whatsapp(response_text)
  File "/app/communication/cliente_vonage.py", line 43, in enviar_whatsapp
    resposta.raise_for_status()
  File "/usr/local/lib/python3.9/site-packages/requests/models.py", line 1026, in raise_for_status
    raise HTTPError(http_error_msg, response=self)
requests.exceptions.HTTPError: 429 Client Error: Too Many Requests for url: https://messages-sandbox.nexmo.com/v1/messages
2025-08-18 14:49:33,833 [ERROR] [root:2049] [_finalize_session] Erro ao enviar mensagem WhatsApp: 429 Client Error: Too Many Requests for url: https://messages-sandbox.nexmo.com/v1/messages
Traceback (most recent call last):
  File "/app/app.py", line 2045, in _finalize_session
    vonage_client.enviar_whatsapp(response_text)
  File "/app/communication/cliente_vonage.py", line 43, in enviar_whatsapp
    resposta.raise_for_status()
  File "/usr/local/lib/python3.9/site-packages/requests/models.py", line 1026, in raise_for_status
    raise HTTPError(http_error_msg, response=self)
requests.exceptions.HTTPError: 429 Client Error: Too Many Requests for url: https://messages-sandbox.nexmo.com/v1/messages
2025-08-18 14:50:15,845 [ERROR] [root:2049] [_finalize_session] Erro ao enviar mensagem WhatsApp: 429 Client Error: Too Many Requests for url: https://messages-sandbox.nexmo.com/v1/messages
Traceback (most recent call last):
  File "/app/app.py", line 2045, in _finalize_session
    vonage_client.enviar_whatsapp(response_text)
  File "/app/communication/cliente_vonage.py", line 43, in enviar_whatsapp
    resposta.raise_for_status()
  File "/usr/local/lib/python3.9/site-packages/requests/models.py", line 1026, in raise_for_status
    raise HTTPError(http_error_msg, response=self)
requests.exceptions.HTTPError: 429 Client Error: Too Many Requests for url: https://messages-sandbox.nexmo.com/v1/messages
2025-08-18 14:57:34,085 [ERROR] [root:2049] [_finalize_session] Erro ao enviar mensagem WhatsApp: 429 Client Error: Too Many Requests for url: https://messages-sandbox.nexmo.com/v1/messages
Traceback (most recent call last):
  File "/app/app.py", line 2045, in _finalize_session
    vonage_client.enviar_whatsapp(response_text)
  File "/app/communication/cliente_vonage.py", line 43, in enviar_whatsapp
    resposta.raise_for_status()
  File "/usr/local/lib/python3.9/site-packages/requests/models.py", line 1026, in raise_for_status
    raise HTTPError(http_error_msg, response=self)
requests.exceptions.HTTPError: 429 Client Error: Too Many Requests for url: https://messages-sandbox.nexmo.com/v1/messages
2025-08-18 17:05:39,201 [ERROR] [root:44] [obter_conexao] Não foi possível conectar ao banco de dados após várias tentativas.
2025-08-18 17:05:39,203 [ERROR] [root:705] [obter_produtos_por_categoria] Erro ao buscar produtos da categoria 'CERVEJA': Não foi possível conectar ao banco de dados.
2025-08-18 17:05:54,237 [ERROR] [root:44] [obter_conexao] Não foi possível conectar ao banco de dados após várias tentativas.
2025-08-18 17:05:54,240 [ERROR] [root:765] [obter_produtos_promocionais_por_categoria] Erro ao buscar promoções da categoria 'CERVEJA': Não foi possível conectar ao banco de dados.
2025-08-18 17:06:09,263 [ERROR] [root:44] [obter_conexao] Não foi possível conectar ao banco de dados após várias tentativas.
2025-08-18 17:06:09,266 [ERROR] [root:167] [obter_produtos_mais_vendidos_por_nome] Erro ao buscar produtos por nome 'cerveja': Não foi possível conectar ao banco de dados.
2025-08-18 17:06:24,292 [ERROR] [root:44] [obter_conexao] Não foi possível conectar ao banco de dados após várias tentativas.
2025-08-18 17:06:24,294 [ERROR] [root:303] [obter_todos_produtos_ativos] Erro ao buscar todos os produtos ativos: Não foi possível conectar ao banco de dados.
2025-08-18 17:09:19,120 [ERROR] [root:44] [obter_conexao] Não foi possível conectar ao banco de dados após várias tentativas.
2025-08-18 17:09:19,123 [ERROR] [root:705] [obter_produtos_por_categoria] Erro ao buscar produtos da categoria 'CERVEJA': Não foi possível conectar ao banco de dados.
2025-08-18 17:27:49,129 [ERROR] [root:2239] [process_message_for_web] WEBCHAT - ERRO CRÍTICO: gerar_busca_otimizada() takes 1 positional argument but 3 were given
Traceback (most recent call last):
  File "/app/app.py", line 2227, in process_message_for_web
    response_text = _route_tool(session, state, intent, sender_id)
  File "/app/app.py", line 1029, in _route_tool
    termo_otimizado = gerar_busca_otimizada(
TypeError: gerar_busca_otimizada() takes 1 positional argument but 3 were given
2025-08-18 18:22:20,941 [ERROR] [root:2300] [process_message_for_web] WEBCHAT - ERRO CRÍTICO: extrair_especificacoes_produto_ia() takes 1 positional argument but 3 were given
Traceback (most recent call last):
  File "/app/app.py", line 2288, in process_message_for_web
    response_text = _route_tool(session, state, intent, sender_id)
  File "/app/app.py", line 1415, in _route_tool
    especificacoes = extrair_especificacoes_produto_ia(
TypeError: extrair_especificacoes_produto_ia() takes 1 positional argument but 3 were given
2025-08-19 23:59:27,526 [ERROR] [root:44] [obter_conexao] Não foi possível conectar ao banco de dados após várias tentativas.
2025-08-19 23:59:27,528 [ERROR] [root:705] [obter_produtos_por_categoria] Erro ao buscar produtos da categoria 'CERVEJA': Não foi possível conectar ao banco de dados.
2025-08-19 23:59:42,569 [ERROR] [root:44] [obter_conexao] Não foi possível conectar ao banco de dados após várias tentativas.
2025-08-19 23:59:42,571 [ERROR] [root:765] [obter_produtos_promocionais_por_categoria] Erro ao buscar promoções da categoria 'CERVEJA': Não foi possível conectar ao banco de dados.
