2025-08-18 14:39:27,208 [ERROR] [root:2049] [_finalize_session] Erro ao enviar mensagem WhatsApp: 429 Client Error: Too Many Requests for url: https://messages-sandbox.nexmo.com/v1/messages
Traceback (most recent call last):
  File "/app/app.py", line 2045, in _finalize_session
    vonage_client.enviar_whatsapp(response_text)
  File "/app/communication/cliente_vonage.py", line 43, in enviar_whatsapp
    resposta.raise_for_status()
  File "/usr/local/lib/python3.9/site-packages/requests/models.py", line 1026, in raise_for_status
    raise HTTPError(http_error_msg, response=self)
requests.exceptions.HTTPError: 429 Client Error: Too Many Requests for url: https://messages-sandbox.nexmo.com/v1/messages
2025-08-18 14:39:42,963 [ERROR] [root:2049] [_finalize_session] Erro ao enviar mensagem WhatsApp: 429 Client Error: Too Many Requests for url: https://messages-sandbox.nexmo.com/v1/messages
Traceback (most recent call last):
  File "/app/app.py", line 2045, in _finalize_session
    vonage_client.enviar_whatsapp(response_text)
  File "/app/communication/cliente_vonage.py", line 43, in enviar_whatsapp
    resposta.raise_for_status()
  File "/usr/local/lib/python3.9/site-packages/requests/models.py", line 1026, in raise_for_status
    raise HTTPError(http_error_msg, response=self)
requests.exceptions.HTTPError: 429 Client Error: Too Many Requests for url: https://messages-sandbox.nexmo.com/v1/messages
2025-08-18 14:40:01,489 [ERROR] [root:2049] [_finalize_session] Erro ao enviar mensagem WhatsApp: 429 Client Error: Too Many Requests for url: https://messages-sandbox.nexmo.com/v1/messages
Traceback (most recent call last):
  File "/app/app.py", line 2045, in _finalize_session
    vonage_client.enviar_whatsapp(response_text)
  File "/app/communication/cliente_vonage.py", line 43, in enviar_whatsapp
    resposta.raise_for_status()
  File "/usr/local/lib/python3.9/site-packages/requests/models.py", line 1026, in raise_for_status
    raise HTTPError(http_error_msg, response=self)
requests.exceptions.HTTPError: 429 Client Error: Too Many Requests for url: https://messages-sandbox.nexmo.com/v1/messages
2025-08-18 14:40:26,378 [ERROR] [root:2049] [_finalize_session] Erro ao enviar mensagem WhatsApp: 429 Client Error: Too Many Requests for url: https://messages-sandbox.nexmo.com/v1/messages
Traceback (most recent call last):
  File "/app/app.py", line 2045, in _finalize_session
    vonage_client.enviar_whatsapp(response_text)
  File "/app/communication/cliente_vonage.py", line 43, in enviar_whatsapp
    resposta.raise_for_status()
  File "/usr/local/lib/python3.9/site-packages/requests/models.py", line 1026, in raise_for_status
    raise HTTPError(http_error_msg, response=self)
requests.exceptions.HTTPError: 429 Client Error: Too Many Requests for url: https://messages-sandbox.nexmo.com/v1/messages
2025-08-18 14:40:41,417 [ERROR] [root:2049] [_finalize_session] Erro ao enviar mensagem WhatsApp: 429 Client Error: Too Many Requests for url: https://messages-sandbox.nexmo.com/v1/messages
Traceback (most recent call last):
  File "/app/app.py", line 2045, in _finalize_session
    vonage_client.enviar_whatsapp(response_text)
  File "/app/communication/cliente_vonage.py", line 43, in enviar_whatsapp
    resposta.raise_for_status()
  File "/usr/local/lib/python3.9/site-packages/requests/models.py", line 1026, in raise_for_status
    raise HTTPError(http_error_msg, response=self)
requests.exceptions.HTTPError: 429 Client Error: Too Many Requests for url: https://messages-sandbox.nexmo.com/v1/messages
2025-08-18 14:40:59,486 [ERROR] [root:2049] [_finalize_session] Erro ao enviar mensagem WhatsApp: 429 Client Error: Too Many Requests for url: https://messages-sandbox.nexmo.com/v1/messages
Traceback (most recent call last):
  File "/app/app.py", line 2045, in _finalize_session
    vonage_client.enviar_whatsapp(response_text)
  File "/app/communication/cliente_vonage.py", line 43, in enviar_whatsapp
    resposta.raise_for_status()
  File "/usr/local/lib/python3.9/site-packages/requests/models.py", line 1026, in raise_for_status
    raise HTTPError(http_error_msg, response=self)
requests.exceptions.HTTPError: 429 Client Error: Too Many Requests for url: https://messages-sandbox.nexmo.com/v1/messages
2025-08-18 14:41:18,344 [ERROR] [root:2049] [_finalize_session] Erro ao enviar mensagem WhatsApp: 429 Client Error: Too Many Requests for url: https://messages-sandbox.nexmo.com/v1/messages
Traceback (most recent call last):
  File "/app/app.py", line 2045, in _finalize_session
    vonage_client.enviar_whatsapp(response_text)
  File "/app/communication/cliente_vonage.py", line 43, in enviar_whatsapp
    resposta.raise_for_status()
  File "/usr/local/lib/python3.9/site-packages/requests/models.py", line 1026, in raise_for_status
    raise HTTPError(http_error_msg, response=self)
requests.exceptions.HTTPError: 429 Client Error: Too Many Requests for url: https://messages-sandbox.nexmo.com/v1/messages
2025-08-18 14:41:46,048 [ERROR] [root:2049] [_finalize_session] Erro ao enviar mensagem WhatsApp: 429 Client Error: Too Many Requests for url: https://messages-sandbox.nexmo.com/v1/messages
Traceback (most recent call last):
  File "/app/app.py", line 2045, in _finalize_session
    vonage_client.enviar_whatsapp(response_text)
  File "/app/communication/cliente_vonage.py", line 43, in enviar_whatsapp
    resposta.raise_for_status()
  File "/usr/local/lib/python3.9/site-packages/requests/models.py", line 1026, in raise_for_status
    raise HTTPError(http_error_msg, response=self)
requests.exceptions.HTTPError: 429 Client Error: Too Many Requests for url: https://messages-sandbox.nexmo.com/v1/messages
2025-08-18 14:43:31,768 [ERROR] [root:2049] [_finalize_session] Erro ao enviar mensagem WhatsApp: 429 Client Error: Too Many Requests for url: https://messages-sandbox.nexmo.com/v1/messages
Traceback (most recent call last):
  File "/app/app.py", line 2045, in _finalize_session
    vonage_client.enviar_whatsapp(response_text)
  File "/app/communication/cliente_vonage.py", line 43, in enviar_whatsapp
    resposta.raise_for_status()
  File "/usr/local/lib/python3.9/site-packages/requests/models.py", line 1026, in raise_for_status
    raise HTTPError(http_error_msg, response=self)
requests.exceptions.HTTPError: 429 Client Error: Too Many Requests for url: https://messages-sandbox.nexmo.com/v1/messages
2025-08-18 14:43:53,659 [ERROR] [root:2049] [_finalize_session] Erro ao enviar mensagem WhatsApp: 429 Client Error: Too Many Requests for url: https://messages-sandbox.nexmo.com/v1/messages
Traceback (most recent call last):
  File "/app/app.py", line 2045, in _finalize_session
    vonage_client.enviar_whatsapp(response_text)
  File "/app/communication/cliente_vonage.py", line 43, in enviar_whatsapp
    resposta.raise_for_status()
  File "/usr/local/lib/python3.9/site-packages/requests/models.py", line 1026, in raise_for_status
    raise HTTPError(http_error_msg, response=self)
requests.exceptions.HTTPError: 429 Client Error: Too Many Requests for url: https://messages-sandbox.nexmo.com/v1/messages
2025-08-18 14:44:22,752 [ERROR] [root:2049] [_finalize_session] Erro ao enviar mensagem WhatsApp: 429 Client Error: Too Many Requests for url: https://messages-sandbox.nexmo.com/v1/messages
Traceback (most recent call last):
  File "/app/app.py", line 2045, in _finalize_session
    vonage_client.enviar_whatsapp(response_text)
  File "/app/communication/cliente_vonage.py", line 43, in enviar_whatsapp
    resposta.raise_for_status()
  File "/usr/local/lib/python3.9/site-packages/requests/models.py", line 1026, in raise_for_status
    raise HTTPError(http_error_msg, response=self)
requests.exceptions.HTTPError: 429 Client Error: Too Many Requests for url: https://messages-sandbox.nexmo.com/v1/messages
2025-08-18 14:44:38,331 [ERROR] [root:2049] [_finalize_session] Erro ao enviar mensagem WhatsApp: 429 Client Error: Too Many Requests for url: https://messages-sandbox.nexmo.com/v1/messages
Traceback (most recent call last):
  File "/app/app.py", line 2045, in _finalize_session
    vonage_client.enviar_whatsapp(response_text)
  File "/app/communication/cliente_vonage.py", line 43, in enviar_whatsapp
    resposta.raise_for_status()
  File "/usr/local/lib/python3.9/site-packages/requests/models.py", line 1026, in raise_for_status
    raise HTTPError(http_error_msg, response=self)
requests.exceptions.HTTPError: 429 Client Error: Too Many Requests for url: https://messages-sandbox.nexmo.com/v1/messages
2025-08-18 14:44:44,117 [ERROR] [root:2049] [_finalize_session] Erro ao enviar mensagem WhatsApp: 429 Client Error: Too Many Requests for url: https://messages-sandbox.nexmo.com/v1/messages
Traceback (most recent call last):
  File "/app/app.py", line 2045, in _finalize_session
    vonage_client.enviar_whatsapp(response_text)
  File "/app/communication/cliente_vonage.py", line 43, in enviar_whatsapp
    resposta.raise_for_status()
  File "/usr/local/lib/python3.9/site-packages/requests/models.py", line 1026, in raise_for_status
    raise HTTPError(http_error_msg, response=self)
requests.exceptions.HTTPError: 429 Client Error: Too Many Requests for url: https://messages-sandbox.nexmo.com/v1/messages
2025-08-18 14:44:58,053 [ERROR] [root:2049] [_finalize_session] Erro ao enviar mensagem WhatsApp: 429 Client Error: Too Many Requests for url: https://messages-sandbox.nexmo.com/v1/messages
Traceback (most recent call last):
  File "/app/app.py", line 2045, in _finalize_session
    vonage_client.enviar_whatsapp(response_text)
  File "/app/communication/cliente_vonage.py", line 43, in enviar_whatsapp
    resposta.raise_for_status()
  File "/usr/local/lib/python3.9/site-packages/requests/models.py", line 1026, in raise_for_status
    raise HTTPError(http_error_msg, response=self)
requests.exceptions.HTTPError: 429 Client Error: Too Many Requests for url: https://messages-sandbox.nexmo.com/v1/messages
2025-08-18 14:45:17,476 [ERROR] [root:2049] [_finalize_session] Erro ao enviar mensagem WhatsApp: 429 Client Error: Too Many Requests for url: https://messages-sandbox.nexmo.com/v1/messages
Traceback (most recent call last):
  File "/app/app.py", line 2045, in _finalize_session
    vonage_client.enviar_whatsapp(response_text)
  File "/app/communication/cliente_vonage.py", line 43, in enviar_whatsapp
    resposta.raise_for_status()
  File "/usr/local/lib/python3.9/site-packages/requests/models.py", line 1026, in raise_for_status
    raise HTTPError(http_error_msg, response=self)
requests.exceptions.HTTPError: 429 Client Error: Too Many Requests for url: https://messages-sandbox.nexmo.com/v1/messages
2025-08-18 14:45:29,425 [ERROR] [root:2049] [_finalize_session] Erro ao enviar mensagem WhatsApp: 429 Client Error: Too Many Requests for url: https://messages-sandbox.nexmo.com/v1/messages
Traceback (most recent call last):
  File "/app/app.py", line 2045, in _finalize_session
    vonage_client.enviar_whatsapp(response_text)
  File "/app/communication/cliente_vonage.py", line 43, in enviar_whatsapp
    resposta.raise_for_status()
  File "/usr/local/lib/python3.9/site-packages/requests/models.py", line 1026, in raise_for_status
    raise HTTPError(http_error_msg, response=self)
requests.exceptions.HTTPError: 429 Client Error: Too Many Requests for url: https://messages-sandbox.nexmo.com/v1/messages
2025-08-18 14:45:42,943 [ERROR] [root:2049] [_finalize_session] Erro ao enviar mensagem WhatsApp: 429 Client Error: Too Many Requests for url: https://messages-sandbox.nexmo.com/v1/messages
Traceback (most recent call last):
  File "/app/app.py", line 2045, in _finalize_session
    vonage_client.enviar_whatsapp(response_text)
  File "/app/communication/cliente_vonage.py", line 43, in enviar_whatsapp
    resposta.raise_for_status()
  File "/usr/local/lib/python3.9/site-packages/requests/models.py", line 1026, in raise_for_status
    raise HTTPError(http_error_msg, response=self)
requests.exceptions.HTTPError: 429 Client Error: Too Many Requests for url: https://messages-sandbox.nexmo.com/v1/messages
2025-08-18 14:46:04,915 [ERROR] [root:2049] [_finalize_session] Erro ao enviar mensagem WhatsApp: 429 Client Error: Too Many Requests for url: https://messages-sandbox.nexmo.com/v1/messages
Traceback (most recent call last):
  File "/app/app.py", line 2045, in _finalize_session
    vonage_client.enviar_whatsapp(response_text)
  File "/app/communication/cliente_vonage.py", line 43, in enviar_whatsapp
    resposta.raise_for_status()
  File "/usr/local/lib/python3.9/site-packages/requests/models.py", line 1026, in raise_for_status
    raise HTTPError(http_error_msg, response=self)
requests.exceptions.HTTPError: 429 Client Error: Too Many Requests for url: https://messages-sandbox.nexmo.com/v1/messages
2025-08-18 14:46:21,744 [ERROR] [root:2049] [_finalize_session] Erro ao enviar mensagem WhatsApp: 429 Client Error: Too Many Requests for url: https://messages-sandbox.nexmo.com/v1/messages
Traceback (most recent call last):
  File "/app/app.py", line 2045, in _finalize_session
    vonage_client.enviar_whatsapp(response_text)
  File "/app/communication/cliente_vonage.py", line 43, in enviar_whatsapp
    resposta.raise_for_status()
  File "/usr/local/lib/python3.9/site-packages/requests/models.py", line 1026, in raise_for_status
    raise HTTPError(http_error_msg, response=self)
requests.exceptions.HTTPError: 429 Client Error: Too Many Requests for url: https://messages-sandbox.nexmo.com/v1/messages
2025-08-18 14:48:28,771 [ERROR] [root:2049] [_finalize_session] Erro ao enviar mensagem WhatsApp: 429 Client Error: Too Many Requests for url: https://messages-sandbox.nexmo.com/v1/messages
Traceback (most recent call last):
  File "/app/app.py", line 2045, in _finalize_session
    vonage_client.enviar_whatsapp(response_text)
  File "/app/communication/cliente_vonage.py", line 43, in enviar_whatsapp
    resposta.raise_for_status()
  File "/usr/local/lib/python3.9/site-packages/requests/models.py", line 1026, in raise_for_status
    raise HTTPError(http_error_msg, response=self)
requests.exceptions.HTTPError: 429 Client Error: Too Many Requests for url: https://messages-sandbox.nexmo.com/v1/messages
2025-08-18 14:48:42,612 [ERROR] [root:2049] [_finalize_session] Erro ao enviar mensagem WhatsApp: 429 Client Error: Too Many Requests for url: https://messages-sandbox.nexmo.com/v1/messages
Traceback (most recent call last):
  File "/app/app.py", line 2045, in _finalize_session
    vonage_client.enviar_whatsapp(response_text)
  File "/app/communication/cliente_vonage.py", line 43, in enviar_whatsapp
    resposta.raise_for_status()
  File "/usr/local/lib/python3.9/site-packages/requests/models.py", line 1026, in raise_for_status
    raise HTTPError(http_error_msg, response=self)
requests.exceptions.HTTPError: 429 Client Error: Too Many Requests for url: https://messages-sandbox.nexmo.com/v1/messages
2025-08-18 14:48:50,974 [ERROR] [root:2049] [_finalize_session] Erro ao enviar mensagem WhatsApp: 429 Client Error: Too Many Requests for url: https://messages-sandbox.nexmo.com/v1/messages
Traceback (most recent call last):
  File "/app/app.py", line 2045, in _finalize_session
    vonage_client.enviar_whatsapp(response_text)
  File "/app/communication/cliente_vonage.py", line 43, in enviar_whatsapp
    resposta.raise_for_status()
  File "/usr/local/lib/python3.9/site-packages/requests/models.py", line 1026, in raise_for_status
    raise HTTPError(http_error_msg, response=self)
requests.exceptions.HTTPError: 429 Client Error: Too Many Requests for url: https://messages-sandbox.nexmo.com/v1/messages
2025-08-18 14:49:07,764 [ERROR] [root:2049] [_finalize_session] Erro ao enviar mensagem WhatsApp: 429 Client Error: Too Many Requests for url: https://messages-sandbox.nexmo.com/v1/messages
Traceback (most recent call last):
  File "/app/app.py", line 2045, in _finalize_session
    vonage_client.enviar_whatsapp(response_text)
  File "/app/communication/cliente_vonage.py", line 43, in enviar_whatsapp
    resposta.raise_for_status()
  File "/usr/local/lib/python3.9/site-packages/requests/models.py", line 1026, in raise_for_status
    raise HTTPError(http_error_msg, response=self)
requests.exceptions.HTTPError: 429 Client Error: Too Many Requests for url: https://messages-sandbox.nexmo.com/v1/messages
2025-08-18 14:49:13,226 [ERROR] [root:2049] [_finalize_session] Erro ao enviar mensagem WhatsApp: 429 Client Error: Too Many Requests for url: https://messages-sandbox.nexmo.com/v1/messages
Traceback (most recent call last):
  File "/app/app.py", line 2045, in _finalize_session
    vonage_client.enviar_whatsapp(response_text)
  File "/app/communication/cliente_vonage.py", line 43, in enviar_whatsapp
    resposta.raise_for_status()
  File "/usr/local/lib/python3.9/site-packages/requests/models.py", line 1026, in raise_for_status
    raise HTTPError(http_error_msg, response=self)
requests.exceptions.HTTPError: 429 Client Error: Too Many Requests for url: https://messages-sandbox.nexmo.com/v1/messages
2025-08-18 14:49:33,833 [ERROR] [root:2049] [_finalize_session] Erro ao enviar mensagem WhatsApp: 429 Client Error: Too Many Requests for url: https://messages-sandbox.nexmo.com/v1/messages
Traceback (most recent call last):
  File "/app/app.py", line 2045, in _finalize_session
    vonage_client.enviar_whatsapp(response_text)
  File "/app/communication/cliente_vonage.py", line 43, in enviar_whatsapp
    resposta.raise_for_status()
  File "/usr/local/lib/python3.9/site-packages/requests/models.py", line 1026, in raise_for_status
    raise HTTPError(http_error_msg, response=self)
requests.exceptions.HTTPError: 429 Client Error: Too Many Requests for url: https://messages-sandbox.nexmo.com/v1/messages
2025-08-18 14:50:15,845 [ERROR] [root:2049] [_finalize_session] Erro ao enviar mensagem WhatsApp: 429 Client Error: Too Many Requests for url: https://messages-sandbox.nexmo.com/v1/messages
Traceback (most recent call last):
  File "/app/app.py", line 2045, in _finalize_session
    vonage_client.enviar_whatsapp(response_text)
  File "/app/communication/cliente_vonage.py", line 43, in enviar_whatsapp
    resposta.raise_for_status()
  File "/usr/local/lib/python3.9/site-packages/requests/models.py", line 1026, in raise_for_status
    raise HTTPError(http_error_msg, response=self)
requests.exceptions.HTTPError: 429 Client Error: Too Many Requests for url: https://messages-sandbox.nexmo.com/v1/messages
2025-08-18 14:57:34,085 [ERROR] [root:2049] [_finalize_session] Erro ao enviar mensagem WhatsApp: 429 Client Error: Too Many Requests for url: https://messages-sandbox.nexmo.com/v1/messages
Traceback (most recent call last):
  File "/app/app.py", line 2045, in _finalize_session
    vonage_client.enviar_whatsapp(response_text)
  File "/app/communication/cliente_vonage.py", line 43, in enviar_whatsapp
    resposta.raise_for_status()
  File "/usr/local/lib/python3.9/site-packages/requests/models.py", line 1026, in raise_for_status
    raise HTTPError(http_error_msg, response=self)
requests.exceptions.HTTPError: 429 Client Error: Too Many Requests for url: https://messages-sandbox.nexmo.com/v1/messages
2025-08-18 17:05:39,201 [ERROR] [root:44] [obter_conexao] Não foi possível conectar ao banco de dados após várias tentativas.
2025-08-18 17:05:39,203 [ERROR] [root:705] [obter_produtos_por_categoria] Erro ao buscar produtos da categoria 'CERVEJA': Não foi possível conectar ao banco de dados.
2025-08-18 17:05:54,237 [ERROR] [root:44] [obter_conexao] Não foi possível conectar ao banco de dados após várias tentativas.
2025-08-18 17:05:54,240 [ERROR] [root:765] [obter_produtos_promocionais_por_categoria] Erro ao buscar promoções da categoria 'CERVEJA': Não foi possível conectar ao banco de dados.
2025-08-18 17:06:09,263 [ERROR] [root:44] [obter_conexao] Não foi possível conectar ao banco de dados após várias tentativas.
2025-08-18 17:06:09,266 [ERROR] [root:167] [obter_produtos_mais_vendidos_por_nome] Erro ao buscar produtos por nome 'cerveja': Não foi possível conectar ao banco de dados.
2025-08-18 17:06:24,292 [ERROR] [root:44] [obter_conexao] Não foi possível conectar ao banco de dados após várias tentativas.
2025-08-18 17:06:24,294 [ERROR] [root:303] [obter_todos_produtos_ativos] Erro ao buscar todos os produtos ativos: Não foi possível conectar ao banco de dados.
2025-08-18 17:09:19,120 [ERROR] [root:44] [obter_conexao] Não foi possível conectar ao banco de dados após várias tentativas.
2025-08-18 17:09:19,123 [ERROR] [root:705] [obter_produtos_por_categoria] Erro ao buscar produtos da categoria 'CERVEJA': Não foi possível conectar ao banco de dados.
2025-08-18 17:27:49,129 [ERROR] [root:2239] [process_message_for_web] WEBCHAT - ERRO CRÍTICO: gerar_busca_otimizada() takes 1 positional argument but 3 were given
Traceback (most recent call last):
  File "/app/app.py", line 2227, in process_message_for_web
    response_text = _route_tool(session, state, intent, sender_id)
  File "/app/app.py", line 1029, in _route_tool
    termo_otimizado = gerar_busca_otimizada(
TypeError: gerar_busca_otimizada() takes 1 positional argument but 3 were given
2025-08-18 18:22:20,941 [ERROR] [root:2300] [process_message_for_web] WEBCHAT - ERRO CRÍTICO: extrair_especificacoes_produto_ia() takes 1 positional argument but 3 were given
Traceback (most recent call last):
  File "/app/app.py", line 2288, in process_message_for_web
    response_text = _route_tool(session, state, intent, sender_id)
  File "/app/app.py", line 1415, in _route_tool
    especificacoes = extrair_especificacoes_produto_ia(
TypeError: extrair_especificacoes_produto_ia() takes 1 positional argument but 3 were given
2025-08-19 23:59:27,526 [ERROR] [root:44] [obter_conexao] Não foi possível conectar ao banco de dados após várias tentativas.
2025-08-19 23:59:27,528 [ERROR] [root:705] [obter_produtos_por_categoria] Erro ao buscar produtos da categoria 'CERVEJA': Não foi possível conectar ao banco de dados.
2025-08-19 23:59:42,569 [ERROR] [root:44] [obter_conexao] Não foi possível conectar ao banco de dados após várias tentativas.
2025-08-19 23:59:42,571 [ERROR] [root:765] [obter_produtos_promocionais_por_categoria] Erro ao buscar promoções da categoria 'CERVEJA': Não foi possível conectar ao banco de dados.
2025-08-20 11:10:04,976 [ERROR] [root:2681] [process_message_for_web] WEBCHAT - ERRO CRÍTICO: module 'db.database' has no attribute 'get_top_selling_products_by_name'
Traceback (most recent call last):
  File "/app/app.py", line 2669, in process_message_for_web
    response_text = _route_tool(session, state, intent, original_sender_id)
  File "/app/app.py", line 1826, in _route_tool
    products = database.get_top_selling_products_by_name(
AttributeError: module 'db.database' has no attribute 'get_top_selling_products_by_name'
2025-08-20 12:18:58,257 [ERROR] [root:140] [detectar_marca_e_produto_ia] [MARCA_PRODUTO_IA] Erro: '"tipo_busca"'
2025-08-20 12:19:32,983 [ERROR] [root:140] [detectar_marca_e_produto_ia] [MARCA_PRODUTO_IA] Erro: '"tipo_busca"'
2025-08-20 12:40:41,898 [ERROR] [root:140] [detectar_marca_e_produto_ia] [MARCA_PRODUTO_IA] Erro: '"tipo_busca"'
2025-08-20 12:46:14,016 [ERROR] [root:140] [detectar_marca_e_produto_ia] [MARCA_PRODUTO_IA] Erro: '"tipo_busca"'
2025-08-20 12:51:33,213 [ERROR] [root:140] [detectar_marca_e_produto_ia] [MARCA_PRODUTO_IA] Erro: '"tipo_busca"'
2025-08-20 12:52:03,024 [ERROR] [root:140] [detectar_marca_e_produto_ia] [MARCA_PRODUTO_IA] Erro: '"tipo_busca"'
2025-08-20 12:52:17,720 [ERROR] [root:140] [detectar_marca_e_produto_ia] [MARCA_PRODUTO_IA] Erro: '"tipo_busca"'
2025-08-20 12:53:08,245 [ERROR] [root:140] [detectar_marca_e_produto_ia] [MARCA_PRODUTO_IA] Erro: '"tipo_busca"'
2025-08-20 13:02:14,284 [ERROR] [root:140] [detectar_marca_e_produto_ia] [MARCA_PRODUTO_IA] Erro: '"tipo_busca"'
2025-08-20 12:14:56,516 [ERROR] [U:test_user] [S:N/A] [gav.gav_logger:196] [log_error] Este é um teste de erro
2025-08-20 15:15:59,324 [CRITICAL] [U:webchat:user_mejwtg6q_oayn3l] [S:N/A] [gav.utils.gav_logger:204] [log_critical] WEBCHAT - ERRO CRÍTICO: "Attempt to overwrite 'user_id' in LogRecord"
Traceback (most recent call last):
  File "/app/app.py", line 2662, in process_message_for_web
    log_info(f"[WEBCHAT] Iniciando validação CNPJ para sender_id: {sender_id}", user_id=sender_id)
  File "/app/utils/gav_logger.py", line 180, in log_info
    logger.info(message, extra=extra_dict)
  File "/usr/local/lib/python3.9/logging/__init__.py", line 1446, in info
    self._log(INFO, msg, args, **kwargs)
  File "/usr/local/lib/python3.9/logging/__init__.py", line 1587, in _log
    record = self.makeRecord(self.name, level, fn, lno, msg, args,
  File "/usr/local/lib/python3.9/logging/__init__.py", line 1561, in makeRecord
    raise KeyError("Attempt to overwrite %r in LogRecord" % key)
KeyError: "Attempt to overwrite 'user_id' in LogRecord"




